[2023-05-04 20:34:28,112] root - ERROR-
        Error occured in script: 
        [ E:\Project\visa\pipeline\pipeline.py ] at 
        try block line number: [32] and exception block line number: [34] 
        error message: [
        Error occured in script: 
        [ E:\Project\visa\pipeline\pipeline.py ] at 
        try block line number: [25] and exception block line number: [28] 
        error message: [get_data_ingestion_config() missing 1 required positional argument: 'self']
        ]
        
