[2023-04-26 21:09:49,107] root - ERROR-
        Error occured in script: 
        [ e:\ML pipeline\visa\pipeline\pipeline.py ] at 
        try block line number: [32] and exception block line number: [34] 
        error message: [
        Error occured in script: 
        [ e:\ML pipeline\visa\pipeline\pipeline.py ] at 
        try block line number: [25] and exception block line number: [28] 
        error message: [get_data_ingestion_config() missing 1 required positional argument: 'self']
        ]
        
